Workbook
Name Surat_I_9_Ref_NomorSuratLowongan: #REF!
Name Surat_I_9_Ref_TanggalSuratLowongan: #REF!
Name Surat_I_9_Tanggal: #REF!

Sheet Lampiran I
E1: Lampiran I
A3: Hasil Verifikasi Calon Penerima Bantuan
A4: Kegiatan Bantuan Stimulan Perumahan Swadaya Tahun 2021
A5: Provinsi Jawa Barat
A7: No | B7: Kabupaten/Kota | C7: CPB (Unit) | D7: Hasil Verifikasi
D8: Lolos (Unit) | E8: Tidak Lolos (Unit) | F8: CPB Pengganti (Unit)
A11: 1 | B11: Kabupaten Tasikmalaya | C11: 80 | D11: 80 | E11: 36 | F11: 36 | H11: MINUS DESA SINDANGSARI BELUM TEREKAP

Sheet II-3
A1: Lembar Verifikasi Calon Penerima Bantuan
A3: Nama KK | C3: : | D3: ….......................................... | F3: Penghasilan KK perbulan | H3: : | I3: …..........................................
A4: NIK | C4: : | D4: ….......................................... | F4: Nilai UMP / UMK (pilih yg tertinggi) | H4: : | I4: …..........................................
A5: Alamat KK | C5: : | D5: ….......................................... | F5: Jenis banper sejenis yang pernah didapat | H5: : | I5: …..........................................
A6: RT / RW | C6: : | D6: ….......................................... | F6: Tahun mendapat banper (0 jika tidak pernah) | H6: : | I6: …..........................................
A7: Desa / Kelurahan | C7: : | D7: ….......................................... | F7: Berapa tahun menghuni rumah | H7: : | I7: …..........................................
A8: Kecamatan | C8: : | D8: ….......................................... | F8: Foto perspektif rumah | H8: : | I8: …..........................................
A9: Kabupaten / Kota | C9: : | D9: ….......................................... | F9: Kode foto rumah / Nama file | H9: : | I9: …..........................................
A10: Provinsi | C10: : | D10: …..........................................
A12: ASPEK / KOMPONEN | C12: KONDISI RUMAH
C13: A | E13: B | H13: C
A14: 1. STRUKTUR
A15: Fondasi | C15: 0 | D15: ada, kondisi baik, kokoh | E15: 0 | F15: ada, sebagian rapuh, tidak kokoh | H15: 0 | I15: tidak ada, seluruhnya rapuh
A16: Sloof | C16: 0 | D16: ada, kondisi baik, kokoh | E16: 0 | F16: ada, sebagian rapuh, tidak kokoh | H16: 0 | I16: tidak ada, seluruhnya rapuh
A17: Kolom | C17: 0 | D17: ada, kondisi baik, kokoh | E17: 0 | F17: ada, sebagian rapuh, tidak kokoh | H17: 0 | I17: tidak ada, seluruhnya rapuh
A18: Ring Balok | C18: 0 | D18: ada, kondisi baik, kokoh | E18: 0 | F18: ada, sebagian rapuh, tidak kokoh | H18: 0 | I18: tidak ada, seluruhnya rapuh
A19: Rangka Atap | C19: 0 | D19: ada, kondisi baik, kokoh | E19: 0 | F19: ada, sebagian rapuh, tidak kokoh | H19: 0 | I19: tidak ada, seluruhnya rapuh
A20: 2. NON-STRUKTUR
A21: Dinding | C21: 0 | D21: Tembok/setengah tembok diplester, papan kayu berkualitas, bahan dinding dengan kondisi kokoh dan kedap air | E21: 0 | F21: tembok kondisi sebagian besar retak, papan atau bahan lain yang kurang kokoh dan tidak kedap air | H21: 0 | I21: anyaman bambu tipis, triplek, papan, tembok, atau bahan lain yang rapuh dan tidak kedap air
A22: Lantai | C22: 0 | D22: Plester/ubin/keramik/ papan/bahan lain kondisi baik, kedap air | E22: 0 | F22: papan atau bahan lain dengan kondisi rusak, plester sebagian besar pecah | H22: 0 | I22: tanah, papan atau bahan lain yang rapuh dan tidak kedap air
A23: Penutup Atap | C23: 0 | D23: genteng/seng/spandek, bahan tradisional (ijuk/rumbia)/bahan lain kondisi baik, tidak bocor | E23: 0 | F23: genteng/seng/spandek, bahan tradisional (ijuk/rumbia)/bahan lain, kondisi rusak sebagian, bocor jika terjadi hujan lebat | H23: 0 | I23: tanah, papan atau bahan lain yang rapuh dan tidak kedap air
A24: 3. KESEHATAN & KECUKUPAN LUAS
A25: Akses Air Minum | C25: 0 | D25: Ada | H25: 0 | I25: Tidak ada
A26: Akses Sanitasi | C26: 0 | D26: Ada | H26: 0 | I26: Tidak ada
A27: Pencahayaan | C27: 0 | D27: Terang, dapat digunakan membaca dengan normal tanpa pencahayaan buatan pada siang hari | E27: 0 | F27: Terang, dapat digunakan membaca dengan normal tanpa pencahayaan buatan pada siang hari | H27: 0 | I27: gelap, tidak dapat digunakan untuk membaca tanpa pencahayaan buatan pada siang hari
A28: Penghawaan | C28: 0 | D28: cukup ventilasi, sirkulasi udara baik | E28: 0 | F28: ventilasi kurang, agak pengap | H28: 0 | I28: tidak ada ventilasi, pengap, lembab
A29: Kecukupan luas ruang | C29: 0 | D29: luas rumah dibagi jumlah penghuni, lebih atau sama dengan 7,2 m² | H29: 0 | I29: luas rumah dibagi jumlah penghuni, kurang dari 7,2 m²
A30: 4. STATUS LAHAN
A31: Status penguasaan lahan | C31: 0 | D31: milik sendiri, ada bukti sah | E31: 0 | F31: sewa/pinjam pakai/izin tinggal/ menumpang, ada bukti sah | H31: 0 | I31: tanpa bukti sah/ilegal
A33: Kesimpulan Kelayakan Rumah | E33: Rekomendasi Penanganan | G33: Nama & TTD Surveyor | I33: Catatan/Isu lainnya
A34: 0 | B34: KK menumpang rumah / rumah tidak ditemukan | E34: =IF(AND($A$36=1,I3<I4,OR(I6=0,I6>10),I7>=3,OR(C31=1,E31=1),E35=0),1,0) -> 0 | F34: Direkomendasikan BSPS saja
A35: 0 | B35: Rumah layak huni (RLH) | E35: =IF(AND(A36=1,OR(H25=1,H26=1)),1,0) -> 0 | F35: Direkomendasikan BSPS dengan dukungan Cipta Karya
A36: 0 | B36: Rumah tidak layak huni (RTLH) | E36: 0 | F36: Perlu dukungan Cipta Karya saja tanpa BSPS
E37: 0 | F37: Tidak dapat dibantu (tulis alasan di kolom catatan)
A39: A. | B39: Dikategorikan rumah tidak layak huni jika menemui minimal satu dari kondisi berikut: | E39: A | F39: Direkomendasikan BSPS jika: 1. syarat RTLH terpenuhi 2. penghasilan perbulan tidak lebih dari Upah Minimum Provinsi/Kab/Kota (UMP atau UMK) 3. tidak pernah mendapat bantuan perumahan sejenis dalam kurun waktu 10 tahun terakhir 4. menghuni/menguasai rumah tidak layak huni selama minimal 3 tahun 5. Status lahan ada bukti sah kepemilikan, penguasaan, atau izin tinggal
A40: 1 | B40: Salah satu komponen struktur bernilai C;
A41: 2 | B41: Dua atau lebih komponen struktur dan non-struktur (lantai, dinding, atap) bernilai B;
A42: 3 | B42: Salah satu komponen non struktur (lantai, dinding, atap) bernilai C; | E42: B | F42: Direkomendasikan BSPS dengan dukungan Cipta Karya jika syarat BSPS terpenuhi dan kondisi sanitasi atau akses air minum bernilai C.
A43: 4 | B43: Komponen kesehatan dan kecukupan luas salah satunya bernilai C. | E43: C | F43: Jika kerusakan rumah hanya pada komponen sanitasi dan/atau air minum, maka perlu dukungan Cipta Karya saja tanpa BSPS.
A44: B | B44: Selain kondisi di atas, atau jika penilaian seluruhnya bernilai A, maka dikategorikan rumah layak huni | E44: D | F44: Kondisi tidak dapat dibantu: 1. Pernah mendapat bantuan sejenis dalam 10 tahun terakhir, penghasilan di atas UMP/UMK, menghuni kurang dari 3 tahun, atau lahan tanpa bukti sah/ilegal; 2. Kerusakan hanya pada aspek pencahayaan atau penghawaan; atau 3. Kerusakan hanya pada kurangnya kecukupan luas ruang.
...

Sheet Source
A1: KOLOM IDENTITAS | B1: KOLOM ISIAN
A2: Kabupaten | B2: BANDUNG | E2: Kabupaten | F2: Kota
A3: Kecamatan | B3: PASEH
A4: Desa | B4: MEKARPAWITAN | E4: Desa | F4: Kelurahan
A5: ="Nama "&IF(A4="Desa","Kepala Desa","Lurah") -> Nama Kepala Desa | B5: Tonton
A6: NIP Lurah *Jika Lurah
A7: ="Nama "&IF(A2="Kabupaten","Korkab","Korkot") -> Nama Korkab | B7: Cahya Purnama, S.Pd
A8: Nama TFL Teknik | B8: Topik, S.T
A9: Nama TFL Pemberdayaan | B9: Yuda Adi Nugraha, S.E
A11: Catatan
A12: 1. Jika ada di Kabupaten tertentu terdapat Kelurahan maka isi pada KOLOM IDENTITAS disesuaikan (Contoh: Kelurahan / Desa

Sheet II-4
V1: Format II-4
V2: REKAPITULASI HASIL VERIFIKASI CALON PENERIMA BANTUAN
A3: REKAPITULASI HASIL VERIFIKASI CALON PENERIMA BANTUAN KEGIATAN BSPS
A5: =Source!A4 -> Desa | D5: =": "&Source!B4 -> : MEKARPAWITAN
A6: =Source!A3 -> Kecamatan | D6: =": "&Source!B3 -> : PASEH
A7: =Source!A2 -> Kabupaten | D7: =": "&Source!B2 -> : BANDUNG
A8: Provinsi | D8: : Jawa Barat | W8: Diisi juga kolom ini
A10: No. | B10: No. BNBA | C10: NAMA | D10: JENIS KELAMIN (L/P) | E10: NIK | F10: NO. KK | G10: ALAMAT TEMPAT TINGGAL | H10: PEMENUHAN KRITERIA *) | N10: HASIL VERIFIKASI | P10: ALASAN TIDAK LOLOS **) | Q10: KESWADAYAAN | S10: PENANGANAN | T10: Titik Koordinat | V10: KET. | W10: TEMPAT & TANGGAL LAHIR CPB | X10: NAMA IBU KANDUNG | Y10: STATUS PERKAWINAN *Sesuai KTP
H11: A | I11: B | J11: C | K11: D | L11: E | M11: F | N11: LOLOS | O11: TIDAK LOLOS | Q11: UANG (RP) | R11: MATERIAL *) | S11: (FEROSEMEN/ KONVENSIONAL/ KAYU | T11: S | U11: E
A12: 1 | B12: 2 | C12: 3 | D12: 4 | E12: 5 | F12: 6 | G12: 7 | H12: 8 | I12: 9 | J12: 10 | K12: 11 | L12: 12 | M12: 13 | N12: 14 | O12: 15 | P12: 16 | Q12: 17 | R12: 18 | S12: 19 | T12: 20 | U12: 21 | V12: 20
A13: 1 | B13: 1 | C13: ODANG | D13: L | E13: 3204350707650002 | F13: 3204350905060028 | G13: KP. JATI RT 03 RW 03 | H13: √ | I13: √ | J13: √ | K13: √ | L13: √ | M13: √ | N13: LOLOS | Q13: 1200000 | S13: KONVENSIONAL | W13: BANDUNG, 07-07-1965 | X13: EEM | Y13: KAWIN | AD13: LOLOS
A14: 2 | B14: 2 | C14: UTAR | D14: L | E14: 3204352101630005 | F14: 3204351303130035 | G14: KP. PUNDEUY RT 01 RW 11 | H14: √ | I14: √ | J14: √ | K14: √ | L14: √ | M14: √ | N14: LOLOS | Q14: 1200000 | S14: KONVENSIONAL | W14: BANDUNG, 21-01-1963 | X14: EMPAT | Y14: KAWIN | AD14: PENGGANTI
A15: 3 | B15: 3 | C15: NENENG WIDIA NINGSIH | D15: P | E15: 3204355408590001 | F15: 3204352308190009 | G15: KP. BARU RT 03 RW 05 | H15: √ | I15: √ | J15: √ | K15: √ | L15: √ | M15: √ | N15: LOLOS | Q15: 1000000 | S15: KONVENSIONAL | W15: BANDUNG, 14-08-1959 | X15: ELI | Y15: KAWIN
A16: 4 | B16: 4 | C16: MAMAN IMRON | D16: L | E16: 3204351306510001 | F16: 3204350407080109 | G16: BOJONG BECIK RT 03 RW 07 | H16: √ | I16: √ | J16: √ | K16: √ | L16: √ | M16: √ | N16: LOLOS | Q16: 1250000 | S16: KONVENSIONAL | W16: BANDUNG,13-06-1951 | X16: AMEH | Y16: KAWIN | AD16: FEROSEMEN
A17: 5 | B17: 5 | C17: KOMARUDIN | D17: L | E17: 3204352012830002 | F17: 3204351906130004 | G17: KP. JATI RT 03 RW 03 | H17: √ | I17: √ | J17: √ | K17: √ | L17: √ | M17: √ | N17: LOLOS | Q17: 1500000 | S17: KONVENSIONAL | W17: BANDUNG, 20-12-1983 | X17: EMING | Y17: KAWIN | AD17: KONVENSIONAL
A18: 6 | B18: 6 | C18: ISAK | D18: L | E18: 3204350406800014 | F18: 3204350605140025 | G18: KP. JATI RT 03 RW 12 | H18: √ | I18: √ | J18: √ | K18: √ | L18: √ | M18: √ | N18: LOLOS | Q18: 1200000 | S18: KONVENSIONAL | W18: BANDUNG, 04-06-1980 | X18: EKAR | Y18: KAWIN | AD18: KAYU
A19: 7 | B19: 7 | C19: INA | D19: P | E19: 3204354810840004 | F19: 3204350208180009 | G19: KP. BOJONG BECIK RT 01 RW 07 | H19: √ | I19: √ | J19: √ | K19: √ | L19: √ | M19: √ | N19: LOLOS | Q19: 1200000 | S19: KONVENSIONAL | W19: BANDUNG, 08-10-1984 | X19: JUA | Y19: KAWIN
A20: 8 | B20: 8 | C20: EUIS KOMARIAH | D20: P | E20: 3204356712640001 | F20: 3204352706080082 | G20: KP. CIPEUNDEUY RT 02 RW 13 | H20: √ | I20: √ | J20: √ | K20: √ | L20: √ | M20: √ | N20: LOLOS | Q20: 1000000 | S20: KONVENSIONAL | W20: BANDUNG, 27-12-1964 | X20: ANAH | Y20: KAWIN
A21: 9 | B21: 9 | C21: HERI HERDIANSYAH | D21: L | E21: 3204152409820005 | F21: 3204352703150017 | G21: KP. SUKASARI RT 03 RW 14 | H21: √ | I21: √ | J21: √ | K21: √ | L21: √ | M21: √ | N21: LOLOS | Q21: 1000000 | S21: KONVENSIONAL | W21: BANDUNG, 24-09-1982 | X21: ENUNG MARYATI | Y21: KAWIN
A22: 10 | B22: 10 | C22: DAYAT HIDAYAT | D22: L | E22: 3204350705820014 | F22: 3204351509080019 | G22: KP. BARU RT 03 RW 05 | H22: √ | I22: √ | J22: √ | K22: √ | L22: √ | M22: √ | N22: LOLOS | Q22: 1200000 | R22: BAMBU | S22: KONVENSIONAL | W22: BANDUNG, 07-05-1982 | X22: IDOH | Y22: KAWIN
A23: 11 | B23: 11 | C23: DEDE | D23: L | E23: 3204350703740003 | F23: 3204352003057917 | G23: KP. BOJONG BECIK RT 03 RW 08 | H23: √ | I23: √ | J23: √ | K23: √ | L23: √ | M23: √ | N23: LOLOS | Q23: 1000000 | S23: KONVENSIONAL | W23: BANDUNG, 07-03-1974 | X23: NUNUNG J | Y23: KAWIN
A24: 12 | B24: 12 | C24: DEDE ATIKAH | D24: P | E24: 3204354203750012 | F24: 3204350307130035 | G24: KP. RANCA RT 03 RW 11 | H24: √ | I24: √ | J24: √ | K24: √ | L24: √ | M24: √ | N24: PENGGANTI | Q24: 1200000 | S24: KONVENSIONAL | W24: BANDUNG, 02-03-1975 | X24: AAN ROHANAH | Y24: KAWIN
A25: 13 | B25: 13 | C25: ANITA PURNAMASARI | D25: P | E25: 3204356008940007 | F25: 3204352703130022 | G25: KAMPUNG CIPEUNDEUY RT 04 RW 06 | H25: √ | I25: √ | J25: √ | K25: √ | L25: √ | M25: √ | N25: PENGGANTI | Q25: 1500000 | S25: KONVENSIONAL | W25: BANUDUNG, 20-08-1994 | X25: YANI SURYANI | Y25: KAWIN
A26: 14 | B26: 14 | C26: CUCU KARTIKA | D26: P | E26: 3204355209770004 | F26: 3204352003050922 | G26: KP. CIPEUNDEUY RT 01 RW 06 | H26: √ | I26: √ | J26: √ | K26: √ | L26: √ | M26: √ | N26: PENGGANTI | Q26: 1000000 | S26: KONVENSIONAL | W26: BANDUNG, 12-09-1977 | X26: IPAH | Y26: KAWIN
A27: 15 | B27: 15 | C27: KOSWANDI | D27: L | E27: 3204352101810001 | F27: 3204351807120017 | G27: KP. CIPEUNDEUY RT 01 RW 06 | H27: √ | I27: √ | J27: √ | K27: √ | L27: √ | M27: √ | N27: PENGGANTI | Q27: 1200000 | S27: KONVENSIONAL | W27: BANDUNG, 21-01-1981 | X27: ELAH | Y27: KAWIN
A28: 16 | B28: 16 | C28: AYI HARDIANSAH | D28: L | E28: 3204350707710003 | F28: 3204350710060019 | G28: KP. JATI RT 01 RW 03 | H28: √ | I28: √ | J28: √ | K28: √ | L28: √ | M28: √ | N28: PENGGANTI | Q28: 1000000 | S28: KONVENSIONAL | W28: BANDUNG, 07-07-1971 | X28: ONAH | Y28: KAWIN
A29: 17 | B29: 17 | C29: DEWI | D29: P | E29: 3204355212730003 | F29: 3204350203070019 | G29: KP. JATI RT 03 RW 04 | H29: √ | I29: √ | J29: √ | K29: √ | L29: √ | M29: √ | N29: PENGGANTI | Q29: 1200000 | S29: KONVENSIONAL | W29: BANDUNG, 12-12-1973 | X29: AYI ROKAYAH | Y29: KAWIN
A30: 18 | B30: 18 | C30: ENTAR | D30: P | E30: 3204354204480006 | F30: 3204351704170023 | G30: BOJONG BECIK RT 01 RW 07 | H30: √ | I30: √ | J30: √ | K30: √ | L30: √ | M30: √ | N30: PENGGANTI | Q30: 1000000 | S30: KONVENSIONAL | W30: BANDUNG, 02-04-1948 | X30: ACIH | Y30: KAWIN
A31: 19 | B31: 19 | C31: ENENG ANI | D31: P | E31: 3204355107900005 | F31: 3204351007120007 | G31: KP. BOJONG BECIK RT 02 RW 08 | H31: √ | I31: √ | J31: √ | K31: √ | L31: √ | M31: √ | N31: PENGGANTI | Q31: 1000000 | S31: KONVENSIONAL | W31: BANDUNG, 11-07-1990 | X31: IDA | Y31: KAWIN
A32: 20 | B32: 20 | C32: ADANG | D32: L | E32: 3204350511720006 | F32: 3204350307130035 | G32: KP. RANCA RT 03 RW 11 | H32: x | I32: x | J32: x | K32: x | L32: x | M32: x | O32: TIDAK LOLOS | P32: 2. Tanah bersengketa/tanpa bukti sah kepemilikan/penguasaan lahan/ilegal;
A33: 21 | B33: 21 | C33: WAWAN SETAIAWAN | D33: L | E33: 3204351406850004 | F33: 3204352703130022 | G33: KAMPUNG CIPEUNDEUY RT 04 RW 06 | H33: x | I33: x | J33: x | K33: x | L33: x | M33: x | O33: TIDAK LOLOS | P33: 9. Lainnya (diisi pada kolom keterangan). | V33: Diganti Oleh Istri
A34: 22 | B34: 22 | C34: TANTAN WINATA | D34: L | E34: 3204340101900020 | F34: 3204351601150011 | G34: KP. CIPEUNDEUY RT 02 RW 06 | H34: x | I34: x | J34: x | K34: x | L34: x | M34: x | O34: TIDAK LOLOS | P34: 2. Tanah bersengketa/tanpa bukti sah kepemilikan/penguasaan lahan/ilegal;
A35: 23 | B35: 23 | C35: APIN | D35: L | E35: 3204351805900005 | F35: 3204351308130019 | G35: KP. CIPEUNDEUY RT 04 RW 06 | H35: x | I35: x | J35: x | K35: x | L35: x | M35: x | O35: TIDAK LOLOS | P35: 5. Pernah memperoleh program bantuan rumah swadaya dan program kemudahan dan bantuan pembiayaan perumahan bagi MBR dalam 10 tahun terakhir;
A36: 24 | B36: 24 | C36: UJANG PARMAN | D36: L | E36: 3204350107670162 | F36: 3204351903056793 | G36: KP. JATI RT 01 RW 03 | H36: x | I36: x | J36: x | K36: x | L36: x | M36: x | O36: TIDAK LOLOS | P36: 2. Tanah bersengketa/tanpa bukti sah kepemilikan/penguasaan lahan/ilegal;
A37: 25 | B37: 25 | C37: AHID HIDAYAT | D37: L | E37: 3204351602700003 | F37: 3204350203070019 | G37: KP. JATI RT 03 RW 04 | H37: x | I37: x | J37: x | K37: x | L37: x | M37: x | O37: TIDAK LOLOS | P37: 9. Lainnya (diisi pada kolom keterangan). | V37: Diganti Oleh Istri
A38: 26 | B38: 26 | C38: HENDRI YUSWANTO | D38: L | E38: 3204350501840002 | F38: 3204352802120016 | G38: KP. SUKASARI RT 03 RW 04 | H38: x | I38: x | J38: x | K38: x | L38: x | M38: x | O38: TIDAK LOLOS | P38: 3. Rumah dalam kondisi layak/rusak ringan;
A39: 27 | B39: 27 | C39: IDA | D39: P | E39: 3204354709600006 | F39: 3204350507080040 | G39: KP. BOJONG BECIK RT 02 RW 08 | H39: x | I39: x | J39: x | K39: x | L39: x | M39: x | O39: TIDAK LOLOS | P39: 3. Rumah dalam kondisi layak/rusak ringan;
A41: Keterangan:
A42: *)Pemenuhan Kriteria, diisi dengan √ = tersedia /memenuhi /layak, x = tidak tersedia/tidak memenuhi/tidak layak: | L42: **) Alasan Tidak Lolos, diisi dengan Angka (1-9) sebagai berikut:
B43: A. WNI berkeluarga; | L43: 1. Belum memiliki KK sendiri;
...

Sheet II-5a
N1: Format II-5
A3: DAFTAR CALON PENERIMA BANTUAN
A4: KEGIATAN BANTUAN STIMULAN PERUMAHAN SWADAYA TAHUN 2026
A5: PROVINSI JAWA BARAT
O6: ='II-4'!W8 -> Diisi juga kolom ini
A8: NO. | B8: KODE KEL | C8: NAMA | D8: JENIS KELAMIN (L/P) | E8: NIK | F8: ALAMAT TEMPAT TINGGAL | G8: =UPPER(Source!A4) -> DESA | H8: KECAMATAN | I8: =UPPER(Source!A2) -> KABUPATEN | J8: *) LOLOS/ PENGGANTI | K8: INSTRUKSI VERIFIKASI | M8: Titik Koordinat | O8: TEMPAT & TANGGAL LAHIR CPB | P8: NAMA IBU KANDUNG | Q8: STATUS PERNIKAHAN *Sesuai dengan KTP
K9: TAHAP | L9: TANGGAL | M9: S | N9: E
A10: 1 | C10: ='II-4'!C13 -> ODANG | D10: ='II-4'!D13 -> L | E10: ='II-4'!E13 -> 3204350707650002 | F10: ='II-4'!G13 -> KP. JATI RT 03 RW 03 | G10: =Source!$B$4 -> MEKARPAWITAN | H10: =Source!$B$3 -> PASEH | I10: =Source!$B$2 -> BANDUNG | J10: LOLOS | K10: II | L10: 46115 | M10: -7.05269753 | N10: 107.78179548 | O10: BANDUNG, 07-07-1965 | P10: EEM | Q10: KAWIN | S10: LOLOS
A11: =A10+1 -> 2 | C11: ='II-4'!C14 -> UTAR | D11: ='II-4'!D14 -> L | E11: ='II-4'!E14 -> 3204352101630005 | F11: ='II-4'!G14 -> KP. PUNDEUY RT 01 RW 11 | G11: =Source!$B$4 -> MEKARPAWITAN | H11: =Source!$B$3 -> PASEH | I11: =Source!$B$2 -> BANDUNG | J11: LOLOS | K11: II | L11: 46115 | M11: -7.04770269 | N11: 107.78043033 | O11: BANDUNG, 21-01-1963 | P11: EMPAT | Q11: KAWIN | S11: PENGGANTI
A12: =A11+1 -> 3 | C12: ='II-4'!C15 -> NENENG WIDIA NINGSIH | D12: ='II-4'!D15 -> P | E12: ='II-4'!E15 -> 3204355408590001 | F12: ='II-4'!G15 -> KP. BARU RT 03 RW 05 | G12: =Source!$B$4 -> MEKARPAWITAN | H12: =Source!$B$3 -> PASEH | I12: =Source!$B$2 -> BANDUNG | J12: LOLOS | K12: II | L12: 46115 | M12: -7.05381054 | N12: 107.78554406 | O12: BANDUNG, 14-08-1959 | P12: ELI | Q12: KAWIN
A13: =A12+1 -> 4 | C13: ='II-4'!C16 -> MAMAN IMRON | D13: ='II-4'!D16 -> L | E13: ='II-4'!E16 -> 3204351306510001 | F13: ='II-4'!G16 -> BOJONG BECIK RT 03 RW 07 | G13: =Source!$B$4 -> MEKARPAWITAN | H13: =Source!$B$3 -> PASEH | I13: =Source!$B$2 -> BANDUNG | J13: LOLOS | K13: II | L13: 46115 | M13: -7.04602555 | N13: 107.78519164 | O13: BANDUNG,13-06-1951 | P13: AMEH | Q13: KAWIN
A14: =A13+1 -> 5 | C14: ='II-4'!C17 -> KOMARUDIN | D14: ='II-4'!D17 -> L | E14: ='II-4'!E17 -> 3204352012830002 | F14: ='II-4'!G17 -> KP. JATI RT 03 RW 03 | G14: =Source!$B$4 -> MEKARPAWITAN | H14: =Source!$B$3 -> PASEH | I14: =Source!$B$2 -> BANDUNG | J14: LOLOS | K14: II | L14: 46115 | M14: -7.05181024 | N14: 107.78167152 | O14: BANDUNG, 20-12-1983 | P14: EMING | Q14: KAWIN
A15: =A14+1 -> 6 | C15: ='II-4'!C18 -> ISAK | D15: ='II-4'!D18 -> L | E15: ='II-4'!E18 -> 3204350406800014 | F15: ='II-4'!G18 -> KP. JATI RT 03 RW 12 | G15: =Source!$B$4 -> MEKARPAWITAN | H15: =Source!$B$3 -> PASEH | I15: =Source!$B$2 -> BANDUNG | J15: LOLOS | K15: II | L15: 46115 | M15: -7.05210601 | N15: 107.78331098 | O15: BANDUNG, 04-06-1980 | P15: EKAR | Q15: KAWIN
A16: =A15+1 -> 7 | C16: ='II-4'!C19 -> INA | D16: ='II-4'!D19 -> P | E16: ='II-4'!E19 -> 3204354810840004 | F16: ='II-4'!G19 -> KP. BOJONG BECIK RT 01 RW 07 | G16: =Source!$B$4 -> MEKARPAWITAN | H16: =Source!$B$3 -> PASEH | I16: =Source!$B$2 -> BANDUNG | J16: LOLOS | K16: II | L16: 46115 | M16: -7.04828123 | N16: 107.78682554 | O16: BANDUNG, 08-10-1984 | P16: JUA | Q16: KAWIN
A17: =A16+1 -> 8 | C17: ='II-4'!C20 -> EUIS KOMARIAH | D17: ='II-4'!D20 -> P | E17: ='II-4'!E20 -> 3204356712640001 | F17: ='II-4'!G20 -> KP. CIPEUNDEUY RT 02 RW 13 | G17: =Source!$B$4 -> MEKARPAWITAN | H17: =Source!$B$3 -> PASEH | I17: =Source!$B$2 -> BANDUNG | J17: LOLOS | K17: II | L17: 46115 | M17: -7.05229207 | N17: 107.78951091 | O17: BANDUNG, 27-12-1964 | P17: ANAH | Q17: KAWIN
A18: =A17+1 -> 9 | C18: ='II-4'!C21 -> HERI HERDIANSYAH | D18: ='II-4'!D21 -> L | E18: ='II-4'!E21 -> 3204152409820005 | F18: ='II-4'!G21 -> KP. SUKASARI RT 03 RW 14 | G18: =Source!$B$4 -> MEKARPAWITAN | H18: =Source!$B$3 -> PASEH | I18: =Source!$B$2 -> BANDUNG | J18: LOLOS | K18: II | L18: 46115 | M18: -7.03636627 | N18: 107.78026375 | O18: BANDUNG, 24-09-1982 | P18: ENUNG MARYATI | Q18: KAWIN
A19: =A18+1 -> 10 | C19: ='II-4'!C22 -> DAYAT HIDAYAT | D19: ='II-4'!D22 -> L | E19: ='II-4'!E22 -> 3204350705820014 | F19: ='II-4'!G22 -> KP. BARU RT 03 RW 05 | G19: =Source!$B$4 -> MEKARPAWITAN | H19: =Source!$B$3 -> PASEH | I19: =Source!$B$2 -> BANDUNG | J19: LOLOS | K19: II | L19: 46115 | M19: -7.05545834 | N19: 107.78798274 | O19: BANDUNG, 07-05-1982 | P19: IDOH | Q19: KAWIN
A20: =A19+1 -> 11 | C20: ='II-4'!C23 -> DEDE | D20: ='II-4'!D23 -> L | E20: ='II-4'!E23 -> 3204350703740003 | F20: ='II-4'!G23 -> KP. BOJONG BECIK RT 03 RW 08 | G20: =Source!$B$4 -> MEKARPAWITAN | H20: =Source!$B$3 -> PASEH | I20: =Source!$B$2 -> BANDUNG | J20: LOLOS | K20: II | L20: 46115 | M20: -7.04647149 | N20: 107.78285953 | O20: BANDUNG, 07-03-1974 | P20: NUNUNG J | Q20: KAWIN
A21: =A20+1 -> 12 | C21: ='II-4'!C24 -> DEDE ATIKAH | D21: ='II-4'!D24 -> P | E21: ='II-4'!E24 -> 3204354203750012 | F21: ='II-4'!G24 -> KP. RANCA RT 03 RW 11 | G21: =Source!$B$4 -> MEKARPAWITAN | H21: =Source!$B$3 -> PASEH | I21: =Source!$B$2 -> BANDUNG | J21: PENGGANTI | K21: II | L21: 46115 | M21: -7.4938953 | N21: 107.78198511 | O21: BANDUNG, 02-03-1975 | P21: AAN ROHANAH | Q21: KAWIN
A22: =A21+1 -> 13 | C22: ='II-4'!C25 -> ANITA PURNAMASARI | D22: ='II-4'!D25 -> P | E22: ='II-4'!E25 -> 3204356008940007 | F22: ='II-4'!G25 -> KAMPUNG CIPEUNDEUY RT 04 RW 06 | G22: =Source!$B$4 -> MEKARPAWITAN | H22: =Source!$B$3 -> PASEH | I22: =Source!$B$2 -> BANDUNG | J22: PENGGANTI | K22: II | L22: 46115 | O22: BANUDUNG, 20-08-1994 | P22: YANI SURYANI | Q22: KAWIN
A23: =A22+1 -> 14 | C23: ='II-4'!C26 -> CUCU KARTIKA | D23: ='II-4'!D26 -> P | E23: ='II-4'!E26 -> 3204355209770004 | F23: ='II-4'!G26 -> KP. CIPEUNDEUY RT 01 RW 06 | G23: =Source!$B$4 -> MEKARPAWITAN | H23: =Source!$B$3 -> PASEH | I23: =Source!$B$2 -> BANDUNG | J23: PENGGANTI | K23: II | L23: 46115 | M23: -7.0543263 | N23: 107.7902855 | O23: BANDUNG, 12-09-1977 | P23: IPAH | Q23: KAWIN
A24: =A23+1 -> 15 | C24: ='II-4'!C27 -> KOSWANDI | D24: ='II-4'!D27 -> L | E24: ='II-4'!E27 -> 3204352101810001 | F24: ='II-4'!G27 -> KP. CIPEUNDEUY RT 01 RW 06 | G24: =Source!$B$4 -> MEKARPAWITAN | H24: =Source!$B$3 -> PASEH | I24: =Source!$B$2 -> BANDUNG | J24: PENGGANTI | K24: II | L24: 46115 | M24: -7.05425763 | N24: 107.79013249 | O24: BANDUNG, 21-01-1981 | P24: ELAH | Q24: KAWIN
A25: =A24+1 -> 16 | C25: ='II-4'!C28 -> AYI HARDIANSAH | D25: ='II-4'!D28 -> L | E25: ='II-4'!E28 -> 3204350707710003 | F25: ='II-4'!G28 -> KP. JATI RT 01 RW 03 | G25: =Source!$B$4 -> MEKARPAWITAN | H25: =Source!$B$3 -> PASEH | I25: =Source!$B$2 -> BANDUNG | J25: PENGGANTI | K25: II | L25: 46115 | M25: -7.05163253 | N25: 107.78087897 | O25: BANDUNG, 07-07-1971 | P25: ONAH | Q25: KAWIN
A26: =A25+1 -> 17 | C26: ='II-4'!C29 -> DEWI | D26: ='II-4'!D29 -> P | E26: ='II-4'!E29 -> 3204355212730003 | F26: ='II-4'!G29 -> KP. JATI RT 03 RW 04 | G26: =Source!$B$4 -> MEKARPAWITAN | H26: =Source!$B$3 -> PASEH | I26: =Source!$B$2 -> BANDUNG | J26: PENGGANTI | K26: II | L26: 46115 | M26: -7.05465683 | N26: 107.78237154 | O26: BANDUNG, 12-12-1973 | P26: AYI ROKAYAH | Q26: KAWIN
A27: =A26+1 -> 18 | C27: ='II-4'!C30 -> ENTAR | D27: ='II-4'!D30 -> P | E27: ='II-4'!E30 -> 3204354204480006 | F27: ='II-4'!G30 -> BOJONG BECIK RT 01 RW 07 | G27: =Source!$B$4 -> MEKARPAWITAN | H27: =Source!$B$3 -> PASEH | I27: =Source!$B$2 -> BANDUNG | J27: PENGGANTI | K27: II | L27: 46115 | M27: -7.04686315 | N27: 107.78587386 | O27: BANDUNG, 02-04-1948 | P27: ACIH | Q27: KAWIN
A28: =A27+1 -> 19 | C28: ='II-4'!C31 -> ENENG ANI | D28: ='II-4'!D31 -> P | E28: ='II-4'!E31 -> 3204355107900005 | F28: ='II-4'!G31 -> KP. BOJONG BECIK RT 02 RW 08 | G28: =Source!$B$4 -> MEKARPAWITAN | H28: =Source!$B$3 -> PASEH | I28: =Source!$B$2 -> BANDUNG | J28: PENGGANTI | K28: II | L28: 46115 | M28: -7.04591283 | N28: 107.78420574 | O28: BANDUNG, 11-07-1990 | P28: IDA | Q28: KAWIN
L30: Diketahui Oleh
L31: =IF('II-4'!A5="Desa","Kepala Desa","Lurah") -> Kepala Desa
L32: =PROPER(Source!B4) -> Mekarpawitan
L37: =Source!B5 -> Tonton
L38: =IF(Source!A4="Desa","","NIP. "&Source!B6)

Sheet II-5b
Q1: Format II-5
A3: DAFTAR CALON PENERIMA BANTUAN PENGGANTI KEGIATAN BANTUAN
A4: STIMULAN PERUMAHAN SWADAYA TAHUN 2025
A5: PROVINSI JAWA BARAT
R6: ='II-5a'!O6 -> Diisi juga kolom ini
A8: NO. | B8: SEBELUM | H8: SESUDAH | M8: INSTRUKSI VERIFIKASI | O8: Titik Koordinat | Q8: KETERANGAN | R8: TEMPAT & TANGGAL LAHIR CPB | S8: NAMA IBU KANDUNG | T8: STATUS PERNIKAHAN *Sesuai dengan KTP
B9: NAMA | C9: JENIS KELAMIN (L/P) | D9: NIK | E9: ALAMAT TEMPAT TINGGAL | F9: =UPPER(Source!A4) -> DESA | G9: ALASAN TIDAK LOLOS *) | H9: NAMA | I9: JENIS KELAMIN (L/P) | J9: NIK | K9: ALAMAT TEMPAT TINGGAL | L9: =UPPER(Source!A4) -> DESA | M9: TAHAP | N9: TANGGAL | O9: S | P9: E
A10: 1 | B10: ADANG | C10: L | D10: 3204350511720006 | E10: KP. RANCA RT 03 RW 11 | F10: =Source!$B$4 -> MEKARPAWITAN | G10: 2. Tanah bersengketa/tanpa bukti sah kepemilikan/penguasaan lahan/ilegal; | H10: DEDE ATIKAH | I10: P | J10: 3204354203750012 | K10: KP. RANCA RT 03 RW 11 | L10: =Source!$B$4 -> MEKARPAWITAN | M10: ='II-5a'!K23 -> II | N10: ='II-5a'!L23 -> 46115 | O10: -7.4938953 | P10: 107.78198511 | R10: BANDUNG, 02-03-1975 | S10: AAN ROHANAH | T10: KAWIN
A11: 2 | B11: WAWAN SETAIAWAN | C11: L | D11: 3204351406850004 | E11: KAMPUNG CIPEUNDEUY RT 04 RW 06 | F11: =Source!$B$4 -> MEKARPAWITAN | G11: 9. Lainnya (diisi pada kolom keterangan). | H11: ANITA PURNAMASARI | I11: P | J11: 3204356008940007 | K11: KAMPUNG CIPEUNDEUY RT 04 RW 06 | L11: =Source!$B$4 -> MEKARPAWITAN | M11: ='II-5a'!K24 -> II | N11: ='II-5a'!L24 -> 46115 | R11: BANUDUNG, 20-08-1994 | S11: YANI SURYANI | T11: KAWIN
A12: 3 | B12: TANTAN WINATA | C12: L | D12: 3204340101900020 | E12: KP. CIPEUNDEUY RT 02 RW 06 | F12: =Source!$B$4 -> MEKARPAWITAN | G12: 2. Tanah bersengketa/tanpa bukti sah kepemilikan/penguasaan lahan/ilegal; | H12: CUCU KARTIKA | I12: P | J12: 3204355209770004 | K12: KP. CIPEUNDEUY RT 01 RW 06 | L12: =Source!$B$4 -> MEKARPAWITAN | M12: ='II-5a'!K25 -> II | N12: ='II-5a'!L25 -> 46115 | O12: -7.0543263 | P12: 107.7902855 | R12: BANDUNG, 12-09-1977 | S12: IPAH | T12: KAWIN
A13: 4 | B13: APIN | C13: L | D13: 3204351805900005 | E13: KP. CIPEUNDEUY RT 04 RW 06 | F13: =Source!$B$4 -> MEKARPAWITAN | G13: 5. Pernah memperoleh program bantuan rumah swadaya dan program kemudahan dan bantuan pembiayaan perumahan bagi MBR dalam 10 tahun terakhir; | H13: KOSWANDI | I13: L | J13: 3204352101810001 | K13: KP. CIPEUNDEUY RT 01 RW 06 | L13: =Source!$B$4 -> MEKARPAWITAN | M13: ='II-5a'!K26 -> II | N13: ='II-5a'!L26 -> 46115 | O13: -7.05425763 | P13: 107.79013249 | R13: BANDUNG, 21-01-1981 | S13: ELAH | T13: KAWIN
A14: 5 | B14: UJANG PARMAN | C14: L | D14: 3204350107670162 | E14: KP. JATI RT 01 RW 03 | F14: =Source!$B$4 -> MEKARPAWITAN | G14: 2. Tanah bersengketa/tanpa bukti sah kepemilikan/penguasaan lahan/ilegal; | H14: AYI HARDIANSAH | I14: L | J14: 3204350707710003 | K14: KP. JATI RT 01 RW 03 | L14: =Source!$B$4 -> MEKARPAWITAN | M14: ='II-5a'!K27 -> II | N14: ='II-5a'!L27 -> 46115 | O14: -7.05163253 | P14: 107.78087897 | R14: BANDUNG, 07-07-1971 | S14: ONAH | T14: KAWIN
A15: 6 | B15: AHID HIDAYAT | C15: L | D15: 3204351602700003 | E15: KP. JATI RT 03 RW 04 | F15: =Source!$B$4 -> MEKARPAWITAN | G15: 9. Lainnya (diisi pada kolom keterangan). | H15: DEWI | I15: P | J15: 3204355212730003 | K15: KP. JATI RT 03 RW 04 | L15: =Source!$B$4 -> MEKARPAWITAN | M15: II | N15: ='II-5a'!L28 -> 46115 | O15: -7.05465683 | P15: 107.78237154 | R15: BANDUNG, 12-12-1973 | S15: AYI ROKAYAH | T15: KAWIN
A16: 7 | B16: HENDRI YUSWANTO | C16: L | D16: 3204350501840002 | E16: KP. SUKASARI RT 03 RW 04 | F16: =Source!$B$4 -> MEKARPAWITAN | G16: 3. Rumah dalam kondisi layak/rusak ringan; | H16: ENTAR | I16: P | J16: 3204354204480006 | K16: BOJONG BECIK RT 01 RW 07 | L16: =Source!$B$4 -> MEKARPAWITAN | M16: II | N16: 46115 | O16: -7.04686315 | P16: 107.78587386 | R16: BANDUNG, 02-04-1948 | S16: ACIH | T16: KAWIN
A17: 8 | B17: IDA | C17: P | D17: 3204354709600006 | E17: KP. BOJONG BECIK RT 02 RW 08 | F17: =Source!$B$4 -> MEKARPAWITAN | G17: 3. Rumah dalam kondisi layak/rusak ringan; | H17: ENENG ANI | I17: P | J17: 3204355107900005 | K17: KP. BOJONG BECIK RT 02 RW 08 | L17: =Source!$B$4 -> MEKARPAWITAN | M17: II | N17: 46115 | O17: -7.04591283 | P17: 107.78420574 | R17: BANDUNG, 11-07-1990 | S17: IDA | T17: KAWIN
B20: Catatan:
B21: *) Alasan Tidak Lolos, diisi dengan Angka (1-9) sebagai berikut:
B22: 1. Belum memiliki KK sendiri;
B23: 2. Tanah bersengketa/tanpa bukti sah kepemilikan/penguasaan lahan/ilegal;
B24: 3. Rumah dalam kondisi layak/rusak ringan;
B25: 4. Memiliki rumah lebih dari 1;
B26: 5. Pernah memperoleh BSPS dalam kurun waktu 10 tahun;
B27: 6. Penghasilan lebih dari ½ UMP/UMK (BSPS Sejahtera); atau Penghasilan lebih dari UMP/UMK (BSPS);
B28: 7. Memilih untuk dibantu dengan sumber anggaran lain;
B29: 8. Menghuni kurang dari 3 tahun;
B30: 9. Lainnya (diisi pada kolom keterangan).
O31: Diketahui Oleh
O32: =IF('II-4'!A5="Desa","Kepala Desa","Lurah") -> Kepala Desa
O33: =PROPER(Source!B4) -> Mekarpawitan
O40: =Source!B5 -> Tonton
O41: =IF(Source!A4="Desa","","NIP. "&Source!B6)
