Workbook
Name Surat_I_9_Ref_NomorSuratLowongan: #REF!
Name Surat_I_9_Ref_TanggalSuratLowongan: #REF!
Name Surat_I_9_Tanggal: #REF!

Sheet Lampiran I
E1: Lampiran I
A3: Hasil Verifikasi Calon Penerima Bantuan
A4: Kegiatan Bantuan Stimulan Perumahan Swadaya Tahun 2021
A5: Provinsi Jawa Barat
A7: No | B7: Kabupaten/Kota | C7: CPB (Unit) | D7: Hasil Verifikasi
D8: Lolos (Unit) | E8: Tidak Lolos (Unit) | F8: CPB Pengganti (Unit)
A11: 1 | B11: Kabupaten Bandung | C11: 32 | D11: 32 | E11: 12 | F11: 0

Sheet II-3
A1: Lembar Verifikasi Calon Penerima Bantuan
A3: Nama KK | C3: : | D3: ….......................................... | F3: Penghasilan KK perbulan | H3: : | I3: …..........................................
A4: NIK | C4: : | D4: ….......................................... | F4: Nilai UMP / UMK (pilih yg tertinggi) | H4: : | I4: …..........................................
A5: Alamat KK | C5: : | D5: ….......................................... | F5: Jenis banper sejenis yang pernah didapat | H5: : | I5: …..........................................
A6: RT / RW | C6: : | D6: ….......................................... | F6: Tahun mendapat banper (0 jika tidak pernah) | H6: : | I6: …..........................................
A7: Desa / Kelurahan | C7: : | D7: ….......................................... | F7: Berapa tahun menghuni rumah | H7: : | I7: …..........................................
A8: Kecamatan | C8: : | D8: ….......................................... | F8: Foto perspektif rumah | H8: : | I8: …..........................................
A9: Kabupaten / Kota | C9: : | D9: ….......................................... | F9: Kode foto rumah / Nama file | H9: : | I9: …..........................................
A10: Provinsi | C10: : | D10: …..........................................
A12: ASPEK / KOMPONEN | C12: KONDISI RUMAH
C13: A | E13: B | H13: C
A14: 1. STRUKTUR
A15: Fondasi | C15: 0 | D15: ada, kondisi baik, kokoh | E15: 0 | F15: ada, sebagian rapuh, tidak kokoh | H15: 0 | I15: tidak ada, seluruhnya rapuh
A16: Sloof | C16: 0 | D16: ada, kondisi baik, kokoh | E16: 0 | F16: ada, sebagian rapuh, tidak kokoh | H16: 0 | I16: tidak ada, seluruhnya rapuh
A17: Kolom | C17: 0 | D17: ada, kondisi baik, kokoh | E17: 0 | F17: ada, sebagian rapuh, tidak kokoh | H17: 0 | I17: tidak ada, seluruhnya rapuh
A18: Ring Balok | C18: 0 | D18: ada, kondisi baik, kokoh | E18: 0 | F18: ada, sebagian rapuh, tidak kokoh | H18: 0 | I18: tidak ada, seluruhnya rapuh
A19: Rangka Atap | C19: 0 | D19: ada, kondisi baik, kokoh | E19: 0 | F19: ada, sebagian rapuh, tidak kokoh | H19: 0 | I19: tidak ada, seluruhnya rapuh
A20: 2. NON-STRUKTUR
A21: Dinding | C21: 0 | D21: Tembok/setengah tembok diplester, papan kayu berkualitas, bahan dinding dengan kondisi kokoh dan kedap air | E21: 0 | F21: tembok kondisi sebagian besar retak, papan atau bahan lain yang kurang kokoh dan tidak kedap air | H21: 0 | I21: anyaman bambu tipis, triplek, papan, tembok, atau bahan lain yang rapuh dan tidak kedap air
A22: Lantai | C22: 0 | D22: Plester/ubin/keramik/ papan/bahan lain kondisi baik, kedap air | E22: 0 | F22: papan atau bahan lain dengan kondisi rusak, plester sebagian besar pecah | H22: 0 | I22: tanah, papan atau bahan lain yang rapuh dan tidak kedap air
A23: Penutup Atap | C23: 0 | D23: genteng/seng/spandek, bahan tradisional (ijuk/rumbia)/bahan lain kondisi baik, tidak bocor | E23: 0 | F23: genteng/seng/spandek, bahan tradisional (ijuk/rumbia)/bahan lain, kondisi rusak sebagian, bocor jika terjadi hujan lebat | H23: 0 | I23: tanah, papan atau bahan lain yang rapuh dan tidak kedap air
A24: 3. KESEHATAN & KECUKUPAN LUAS
A25: Akses Air Minum | C25: 0 | D25: Ada | H25: 0 | I25: Tidak ada
A26: Akses Sanitasi | C26: 0 | D26: Ada | H26: 0 | I26: Tidak ada
A27: Pencahayaan | C27: 0 | D27: Terang, dapat digunakan membaca dengan normal tanpa pencahayaan buatan pada siang hari | E27: 0 | F27: Terang, dapat digunakan membaca dengan normal tanpa pencahayaan buatan pada siang hari | H27: 0 | I27: gelap, tidak dapat digunakan untuk membaca tanpa pencahayaan buatan pada siang hari
A28: Penghawaan | C28: 0 | D28: cukup ventilasi, sirkulasi udara baik | E28: 0 | F28: ventilasi kurang, agak pengap | H28: 0 | I28: tidak ada ventilasi, pengap, lembab
A29: Kecukupan luas ruang | C29: 0 | D29: luas rumah dibagi jumlah penghuni, lebih atau sama dengan 7,2 m² | H29: 0 | I29: luas rumah dibagi jumlah penghuni, kurang dari 7,2 m²
A30: 4. STATUS LAHAN
A31: Status penguasaan lahan | C31: 0 | D31: milik sendiri, ada bukti sah | E31: 0 | F31: sewa/pinjam pakai/izin tinggal/ menumpang, ada bukti sah | H31: 0 | I31: tanpa bukti sah/ilegal
A33: Kesimpulan Kelayakan Rumah | E33: Rekomendasi Penanganan | G33: Nama & TTD Surveyor | I33: Catatan/Isu lainnya
A34: 0 | B34: KK menumpang rumah / rumah tidak ditemukan | E34: =IF(AND($A$36=1,I3<I4,OR(I6=0,I6>10),I7>=3,OR(C31=1,E31=1),E35=0),1,0) | F34: Direkomendasikan BSPS saja
A35: 0 | B35: Rumah layak huni (RLH) | E35: =IF(AND(A36=1,OR(H25=1,H26=1)),1,0) | F35: Direkomendasikan BSPS dengan dukungan Cipta Karya
A36: 0 | B36: Rumah tidak layak huni (RTLH) | E36: 0 | F36: Perlu dukungan Cipta Karya saja tanpa BSPS
E37: 0 | F37: Tidak dapat dibantu (tulis alasan di kolom catatan)
A39: A. | B39: Dikategorikan rumah tidak layak huni jika menemui minimal satu dari kondisi berikut: | E39: A | F39: Direkomendasikan BSPS jika: 1. syarat RTLH terpenuhi 2. penghasilan perbulan tidak lebih dari Upah Minimum Provinsi/Kab/Kota (UMP atau UMK) 3. tidak pernah mendapat bantuan perumahan sejenis dalam kurun waktu 10 tahun terakhir 4. menghuni/menguasai rumah tidak layak huni selama minimal 3 tahun 5. Status lahan ada bukti sah kepemilikan, penguasaan, atau izin tinggal
A40: 1 | B40: Salah satu komponen struktur bernilai C;
A41: 2 | B41: Dua atau lebih komponen struktur dan non-struktur (lantai, dinding, atap) bernilai B;
A42: 3 | B42: Salah satu komponen non struktur (lantai, dinding, atap) bernilai C; | E42: B | F42: Direkomendasikan BSPS dengan dukungan Cipta Karya jika syarat BSPS terpenuhi dan kondisi sanitasi atau akses air minum bernilai C.
A43: 4 | B43: Komponen kesehatan dan kecukupan luas salah satunya bernilai C. | E43: C | F43: Jika kerusakan rumah hanya pada komponen sanitasi dan/atau air minum, maka perlu dukungan Cipta Karya saja tanpa BSPS.
A44: B | B44: Selain kondisi di atas, atau jika penilaian seluruhnya bernilai A, maka dikategorikan rumah layak huni | E44: D | F44: Kondisi tidak dapat dibantu: 1. Pernah mendapat bantuan sejenis dalam 10 tahun terakhir, penghasilan di atas UMP/UMK, menghuni kurang dari 3 tahun, atau lahan tanpa bukti sah/ilegal; 2. Kerusakan hanya pada aspek pencahayaan atau penghawaan; atau 3. Kerusakan hanya pada kurangnya kecukupan luas ruang.
...

Sheet Source
A1: KOLOM IDENTITAS | B1: KOLOM ISIAN
A2: Kabupaten | B2: BANDUNG | E2: Kabupaten | F2: Kota
A3: Kecamatan | B3: PASEH
A4: Desa | B4: LOA | E4: Desa | F4: Kelurahan
A5: ="Nama "&IF(A4="Desa","Kepala Desa","Lurah") | B5: ...
A6: NIP Lurah *Jika Lurah
A7: ="Nama "&IF(A2="Kabupaten","Korkab","Korkot") | B7: ...
A8: Nama TFL Teknik | B8: ...
A9: Nama TFL Pemberdayaan | B9: ...
A11: Catatan
A12: 1. Jika ada di Kabupaten tertentu terdapat Kelurahan maka isi pada KOLOM IDENTITAS disesuaikan (Contoh: Kelurahan / Desa

Sheet II-4
V1: Format II-4
V2: REKAPITULASI HASIL VERIFIKASI CALON PENERIMA BANTUAN
A3: REKAPITULASI HASIL VERIFIKASI CALON PENERIMA BANTUAN KEGIATAN BSPS
A5: =Source!A4 | D5: =": "&Source!B4
A6: =Source!A3 | D6: =": "&Source!B3
A7: =Source!A2 | D7: =": "&Source!B2
A8: Provinsi | D8: : Jawa Barat | W8: Diisi juga kolom ini
A10: No. | B10: No. BNBA | C10: NAMA | D10: JENIS KELAMIN (L/P) | E10: NIK | F10: NO. KK | G10: ALAMAT TEMPAT TINGGAL | H10: PEMENUHAN KRITERIA *) | N10: HASIL VERIFIKASI | P10: ALASAN TIDAK LOLOS **) | Q10: KESWADAYAAN | S10: PENANGANAN | T10: Titik Koordinat | V10: KET. | W10: TEMPAT & TANGGAL LAHIR CPB | X10: NAMA IBU KANDUNG | Y10: STATUS PERKAWINAN *Sesuai KTP
H11: A | I11: B | J11: C | K11: D | L11: E | M11: F | N11: LOLOS | O11: TIDAK LOLOS | Q11: UANG (RP) | R11: MATERIAL *) | S11: (FEROSEMEN/ KONVENSIONAL/ KAYU | T11: S | U11: E
A12: 1 | B12: 2 | C12: 3 | D12: 4 | E12: 5 | F12: 6 | G12: 7 | H12: 8 | I12: 9 | J12: 10 | K12: 11 | L12: 12 | M12: 13 | N12: 14 | O12: 15 | P12: 16 | Q12: 17 | R12: 18 | S12: 19 | T12: 20 | U12: 21 | V12: 20
A13: 1 | B13: 1 | C13: AAM | E13: 3204350610650002 | F13: 3204352312050145 | G13: KP LENGGO RT 2 RW 11 | H13: √ | I13: √ | J13: √ | K13: √ | L13: √ | M13: √ | N13: LOLOS | T13: -7.066851 | U13: 107.78176
A14: 2 | B14: 2 | C14: ENGKUS | E14: 3204350408910001 | F14: 3204350807190015 | G14: KP TIISDINGIN RT 2 RW 6 | H14: √ | I14: √ | J14: √ | K14: √ | L14: √ | M14: √ | N14: LOLOS | T14: -7.0787137 | U14: 107.79092
A15: 3 | B15: 3 | C15: SARIFUDIN | E15: 3204352307940008 | F15: 3204352609140021 | G15: KP LOA RT 3 RW 10 | H15: √ | I15: √ | J15: √ | K15: √ | L15: √ | M15: √ | N15: LOLOS | T15: -7.0748432 | U15: 107.78681
A16: 4 | B16: 4 | C16: AHMAD | E16: 3204351702540001 | F16: 3204352508050248 | G16: KP CILOPANG 001/003 RT 01 RW 03 | H16: √ | I16: √ | J16: √ | K16: √ | L16: √ | M16: √ | N16: LOLOS | T16: -7.0828349 | U16: 107.79459
A17: 5 | B17: 5 | C17: ASEP AAN SAEPUDIN | E17: 3204350901750002 | F17: 3204351208160008 | G17: KP LOA RT 01/01 | H17: √ | I17: √ | J17: √ | K17: √ | L17: √ | M17: √ | N17: LOLOS | T17: -7.0699309 | U17: 107.78665
A18: 6 | B18: 6 | C18: DANA | E18: 3204352610750003 | F18: 3204351903051537 | G18: KP SUKA GEUNAH RT 01/05 | H18: √ | I18: √ | J18: √ | K18: √ | L18: √ | M18: √ | N18: LOLOS | T18: -7.0781197 | U18: 107.78833
A19: 7 | B19: 7 | C19: NURHAYATI | E19: 3204354805770008 | F19: 3204351903050323 | G19: KP CILOPANG RT 02 RW 07 | H19: √ | I19: √ | J19: √ | K19: √ | L19: √ | M19: √ | N19: LOLOS | T19: -7.0848874 | U19: 107.79679
A20: 8 | B20: 8 | C20: TARLAN | E20: 3204351808630003 | F20: 3204352405110065 | G20: KP CILOPANG RT 04/07 | H20: √ | I20: √ | J20: √ | K20: √ | L20: √ | M20: √ | N20: LOLOS | T20: -7.0833332 | U20: 107.7936
A21: 9 | B21: 9 | C21: ICAH | E21: 3204354107710061 | F21: 3204352304200006 | G21: Sempak RT 003 RW 005 | H21: √ | I21: √ | J21: √ | K21: √ | L21: √ | M21: √ | N21: LOLOS | T21: -7.0794643 | U21: 107.78655
A22: 10 | B22: 10 | C22: ADE | E22: 3204351205630001 | F22: 3204351903050814 | G22: KP MALANG RT 5 RW 6 | H22: √ | I22: √ | J22: √ | K22: √ | L22: √ | M22: √ | N22: LOLOS | T22: -7.0814522 | U22: 107.79558
A23: 11 | B23: 11 | C23: ANAH | E23: 3204354304480004 | F23: 3204352201200003 | G23: KP NENGENG RT 2 RW 4 | H23: √ | I23: √ | J23: √ | K23: √ | L23: √ | M23: √ | N23: LOLOS | T23: -7.0897378 | U23: 107.78744
A24: 12 | B24: 12 | C24: WAHYU WIBISANA | E24: 3204353112600001 | F24: 3204350701060146 | G24: LIMUS MANGGUNG RT 3 RW 8 | H24: √ | I24: √ | J24: √ | K24: √ | L24: √ | M24: √ | N24: LOLOS | T24: -7.0960722 | U24: 107.79013
... A31: 19 | B31: 19 | C31: ADANG | E31: 3204352905890001 | F31: 3204351612210006 | G31: KP. CIDADAP RT 5 RW 5 | H31: √ | I31: √ | J31: √ | K31: √ | L31: √ | M31: √ | N31: LOLOS | T31: -7.0727204 | U31: 107.78009
A32: 20 | B32: 20 | C32: DENI HERMANTO | G32: KP. Loa | H32: √ | I32: √ | J32: √ | K32: √ | L32: √ | M32: √ | N32: LOLOS | T32: -7.0677971 | U32: 107.7849
A33: 21 | B33: 21 | C33: ENDANG | E33: 3204352504720003 | F33: 3204352508050102 | G33: KP LOA RT 3 RW 10 | H33: x | I33: x | J33: x | K33: x | L33: x | M33: x | O33: TIDAK LOLOS | P33: 3. Rumah dalam kondisi layak/rusak ringan; | T33: -7.0744816 | U33: 107.78845 | V33: Layak Huni - Dibangun Pribadi
A34: 22 | B34: 22 | C34: LALAN | E34: 3204364406880002 | F34: 3204361108120039 | G34: KP CANAR RT 1 RW 12 | H34: x | I34: x | J34: x | K34: x | L34: x | M34: x | O34: TIDAK LOLOS | P34: 3. Rumah dalam kondisi layak/rusak ringan; | T34: -7.0847229 | U34: 107.79085 | V34: Layak Huni - Dibangun Pribadi
A35: 23 | B35: 23 | C35: U.ODIN | E35: 3204351108770005 | F35: 3204351009120001 | G35: KP MEKAR SARI RT 3 RW 9 | H35: x | I35: x | J35: x | K35: x | L35: x | M35: x | O35: TIDAK LOLOS | P35: 3. Rumah dalam kondisi layak/rusak ringan; | T35: -7.0740643 | U35: 107.79139 | V35: Layak Huni - Dibangun Pribadi
A36: 24 | B36: 24 | C36: TOTO TARMALA | E36: 3204350101920001 | F36: 3204351803050561 | G36: KP LOA RT 4 RW 2 | H36: x | I36: x | J36: x | K36: x | L36: x | M36: x | O36: TIDAK LOLOS | P36: 3. Rumah dalam kondisi layak/rusak ringan; | T36: -7.0740836 | U36: 107.78814 | V36: Layak Huni - Dibangun Pribadi
A37: 25 | B37: 25 | C37: UJANG TIMAN | E37: 3204351508760018 | F37: 3204351211130013 | G37: KP LOA RT 4 RW 2 | H37: x | I37: x | J37: x | K37: x | L37: x | M37: x | O37: TIDAK LOLOS | P37: 3. Rumah dalam kondisi layak/rusak ringan; | T37: -7.0739378 | U37: 107.78835 | V37: Layak Huni - Dibangun Pribadi
A38: 26 | B38: 26 | C38: EMEH | E38: 3204354107590197 | F38: 3204352210070031 | G38: MALINGPING RT 4 RW 8 | H38: x | I38: x | J38: x | K38: x | L38: x | M38: x | O38: TIDAK LOLOS | P38: 3. Rumah dalam kondisi layak/rusak ringan; | T38: -7.096682 | U38: 107.78985 | V38: Layak Huni - Dibangun Pribadi
A39: 27 | B39: 27 | C39: TATAN RUSTANDI | E39: 3203151003900004 | F39: 3204350304200001 | G39: KP LOA RT 4 RW 2 | H39: x | I39: x | J39: x | K39: x | L39: x | M39: x | O39: TIDAK LOLOS | P39: 3. Rumah dalam kondisi layak/rusak ringan; | T39: -7.0742444 | U39: 107.78845 | V39: Layak Huni - Dibangun Pribadi
A40: 28 | B40: 28 | C40: HADI | E40: 3204352502820008 | F40: 3204351004070008 | G40: CIDADAP RT 5 RW 5 | H40: x | I40: x | J40: x | K40: x | L40: x | M40: x | O40: TIDAK LOLOS | P40: 3. Rumah dalam kondisi layak/rusak ringan; | T40: -7.0847835 | U40: 107.79097 | V40: Layak Huni - Dibantu Desa
A41: 29 | B41: 29 | C41: ILPAN SETIA MULYA | E41: 3204332811900005 | F41: 3204352506130041 | G41: KP. TIISDINGIN RT 1 RW 6 | H41: x | I41: x | J41: x | K41: x | L41: x | M41: x | O41: TIDAK LOLOS | P41: 3. Rumah dalam kondisi layak/rusak ringan; | T41: -7.077608 | U41: 107.7918 | V41: Layak Huni - Dibangun Pribadi
A42: 30 | B42: 30 | C42: SAEPULOH | E42: 3204351406940003 | F42: 3204352909220007 | G42: KP. LOA RT 3 RW 10 | H42: x | I42: x | J42: x | K42: x | L42: x | M42: x | O42: TIDAK LOLOS | P42: 3. Rumah dalam kondisi layak/rusak ringan; | T42: -7.0746261 | U42: 107.78839 | V42: Layak Huni - Tidak Ditempati
A43: 31 | B43: 31 | C43: EHA | E43: 3204355002550004 | F43: 3204353009220015 | G43: KP. LOA RT 3 RW 10 | H43: x | I43: x | J43: x | K43: x | L43: x | M43: x | O43: TIDAK LOLOS | P43: 3. Rumah dalam kondisi layak/rusak ringan; | T43: -7.0751748 | U43: 107.78659 | V43: Layak Huni - Dibantu Desa
A44: 32 | B44: 32 | C44: WARSA | E44: 3204351002711001 | F44: 3204351609140013 | G44: KP. BUKATANAH RT 2 RW 3 | H44: x | I44: x | J44: x | K44: x | L44: x | M44: x | O44: TIDAK LOLOS | P44: 9. Lainnya (Tidak ingin melanjutkan). | T44: -7.0857243 | U44: 107.79674 | V44: Tidak Ingin Melanjutkan
A46: Keterangan:
A47: *)Pemenuhan Kriteria, diisi dengan √ = tersedia /memenuhi /layak, x = tidak tersedia/tidak memenuhi/tidak layak: | L47: **) Alasan Tidak Lolos, diisi dengan Angka (1-9) sebagai berikut:
B48: A. WNI berkeluarga; | L48: 1. Belum memiliki KK sendiri;
B49: B. Memiliki/menguasai tanah dengan alas hak yang sah; | L49: 2. Tanah bersengketa/tanpa bukti sah kepemilikan/penguasaan lahan/ilegal;
...

Sheet II-5a
N1: Format II-5
A3: DAFTAR CALON PENERIMA BANTUAN
A4: KEGIATAN BANTUAN STIMULAN PERUMAHAN SWADAYA TAHUN 2026
A5: PROVINSI JAWA BARAT
O6: ='II-4'!W8
A8: NO. | B8: KODE KEL | C8: NAMA | D8: JENIS KELAMIN (L/P) | E8: NIK | F8: ALAMAT TEMPAT TINGGAL | G8: =UPPER(Source!A4) | H8: KECAMATAN | I8: =UPPER(Source!A2) | J8: *) LOLOS/ PENGGANTI | K8: INSTRUKSI VERIFIKASI | M8: Titik Koordinat | O8: TEMPAT & TANGGAL LAHIR CPB | P8: NAMA IBU KANDUNG | Q8: STATUS PERNIKAHAN *Sesuai dengan KTP
K9: TAHAP | L9: TANGGAL | M9: S | N9: E
A10: 1 | C10: AAM | E10: 3204350610650002 | F10: KP LENGGO RT 2 RW 11 | J10: LOLOS | M10: -7.066851 | N10: 107.78176 | S10: LOLOS
A11: 2 | C11: ENGKUS | E11: 3204350408910001 | F11: KP TIISDINGIN RT 2 RW 6 | J11: LOLOS | M11: -7.0787137 | N11: 107.79092 | S11: LOLOS
A12: 3 | C12: SARIFUDIN | E12: 3204352307940008 | F12: KP LOA RT 3 RW 10 | J12: LOLOS | M12: -7.0748432 | N12: 107.78681 | S12: LOLOS
A13: 4 | C13: AHMAD | E13: 3204351702540001 | F13: KP CILOPANG 001/003 RT 01 RW 03 | J13: LOLOS | M13: -7.0828349 | N13: 107.79459 | S13: LOLOS
A14: 5 | C14: ASEP AAN SAEPUDIN | E14: 3204350901750002 | F14: KP LOA RT 01/01 | J14: LOLOS | M14: -7.0699309 | N14: 107.78665 | S14: LOLOS
A15: 6 | C15: DANA | E15: 3204352610750003 | F15: KP SUKA GEUNAH RT 01/05 | J15: LOLOS | M15: -7.0781197 | N15: 107.78833 | S15: LOLOS
A16: 7 | C16: NURHAYATI | E16: 3204354805770008 | F16: KP CILOPANG RT 02 RW 07 | J16: LOLOS | M16: -7.0848874 | N16: 107.79679 | S16: LOLOS
A17: 8 | C17: TARLAN | E17: 3204351808630003 | F17: KP CILOPANG RT 04/07 | J17: LOLOS | M17: -7.0833332 | N17: 107.7936 | S17: LOLOS
A18: 9 | C18: ICAH | E18: 3204354107710061 | F18: Sempak RT 003 RW 005 | J18: LOLOS | M18: -7.0794643 | N18: 107.78655 | S18: LOLOS
A19: 10 | C19: ADE | E19: 3204351205630001 | F19: KP MALANG RT 5 RW 6 | J19: LOLOS | M19: -7.0814522 | N19: 107.79558 | S19: LOLOS
A20: 11 | C20: ANAH | E20: 3204354304480004 | F20: KP NENGENG RT 2 RW 4 | J20: LOLOS | M20: -7.0897378 | N20: 107.78744 | S20: LOLOS
A21: 12 | C21: WAHYU WIBISANA | E21: 3204353112600001 | F21: LIMUS MANGGUNG RT 3 RW 8 | J21: LOLOS | M21: -7.0960722 | N21: 107.79013 | S21: LOLOS
... A28: 19 | C28: ADANG | E28: 3204352905890001 | F28: KP. CIDADAP RT 5 RW 5 | J28: LOLOS | M28: -7.0727204 | N28: 107.78009 | S28: LOLOS
A29: 20 | C29: DENI HERMANTO | F29: KP. Loa | J29: LOLOS | M29: -7.0677971 | N29: 107.7849 | S29: LOLOS
L31: Diketahui Oleh
L32: =IF('II-4'!A5="Desa","Kepala Desa","Lurah")
L33: =PROPER(Source!B4)
L38: =Source!B5
L39: =IF(Source!A4="Desa","","NIP. "&Source!B6)

Sheet II-5b
Q1: Format II-5
A3: DAFTAR CALON PENERIMA BANTUAN PENGGANTI KEGIATAN BANTUAN
A4: STIMULAN PERUMAHAN SWADAYA TAHUN 2025
A5: PROVINSI JAWA BARAT
R6: ='II-5a'!O6
A8: NO. | B8: SEBELUM | H8: SESUDAH | M8: INSTRUKSI VERIFIKASI | O8: Titik Koordinat | Q8: KETERANGAN | R8: TEMPAT & TANGGAL LAHIR CPB | S8: NAMA IBU KANDUNG | T8: STATUS PERNIKAHAN *Sesuai dengan KTP
B9: NAMA | C9: JENIS KELAMIN (L/P) | D9: NIK | E9: ALAMAT TEMPAT TINGGAL | F9: =UPPER(Source!A4) | G9: ALASAN TIDAK LOLOS *) | H9: NAMA | I9: JENIS KELAMIN (L/P) | J9: NIK | K9: ALAMAT TEMPAT TINGGAL | L9: =UPPER(Source!A4) | M9: TAHAP | N9: TANGGAL | O9: S | P9: E
A10: 1 | B10: ENDANG | D10: 3204352504720003 | E10: KP LOA RT 3 RW 10 | G10: 3. Rumah dalam kondisi layak/rusak ringan; | O10: -7.0744816 | P10: 107.78845
A11: 2 | B11: LALAN | D11: 3204364406880002 | E11: KP CANAR RT 1 RW 12 | G11: 3. Rumah dalam kondisi layak/rusak ringan; | O11: -7.0847229 | P11: 107.79085
A12: 3 | B12: U.ODIN | D12: 3204351108770005 | E12: KP MEKAR SARI RT 3 RW 9 | G12: 3. Rumah dalam kondisi layak/rusak ringan; | O12: -7.0740643 | P12: 107.79139
A13: 4 | B13: TOTO TARMALA | D13: 3204350101920001 | E13: KP LOA RT 4 RW 2 | G13: 3. Rumah dalam kondisi layak/rusak ringan; | O13: -7.0740836 | P13: 107.78814
A14: 5 | B14: UJANG TIMAN | D14: 3204351508760018 | E14: KP LOA RT 4 RW 2 | G14: 3. Rumah dalam kondisi layak/rusak ringan; | O14: -7.0739378 | P14: 107.78835
A15: 6 | B15: EMEH | D15: 3204354107590197 | E15: MALINGPING RT 4 RW 8 | G15: 3. Rumah dalam kondisi layak/rusak ringan; | O15: -7.096682 | P15: 107.78985
A16: 7 | B16: TATAN RUSTANDI | D16: 3203151003900004 | E16: KP LOA RT 4 RW 2 | G16: 3. Rumah dalam kondisi layak/rusak ringan; | O16: -7.0742444 | P16: 107.78845
A17: 8 | B17: HADI | D17: 3204352502820008 | E17: CIDADAP RT 5 RW 5 | G17: 3. Rumah dalam kondisi layak/rusak ringan; | O17: -7.0847835 | P17: 107.79097
A18: 9 | B18: ILPAN SETIA MULYA | D18: 3204332811900005 | E18: KP. TIISDINGIN RT 1 RW 6 | G18: 3. Rumah dalam kondisi layak/rusak ringan; | O18: -7.077608 | P18: 107.7918
A19: 10 | B19: SAEPULOH | D19: 3204351406940003 | E19: KP. LOA RT 3 RW 10 | G19: 3. Rumah dalam kondisi layak/rusak ringan; | O19: -7.0746261 | P19: 107.78839
A20: 11 | B20: EHA | D20: 3204355002550004 | E20: KP. LOA RT 3 RW 10 | G20: 3. Rumah dalam kondisi layak/rusak ringan; | O20: -7.0751748 | P20: 107.78659
A21: 12 | B21: WARSA | D21: 3204351002711001 | E21: KP. BUKATANAH RT 2 RW 3 | G21: 9. Lainnya (Tidak ingin melanjutkan). | O21: -7.0857243 | P21: 107.79674
B24: Catatan:
B25: *) Alasan Tidak Lolos, diisi dengan Angka (1-9) sebagai berikut:
B26: 1. Belum memiliki KK sendiri;
B27: 2. Tanah bersengketa/tanpa bukti sah kepemilikan/penguasaan lahan/ilegal;
B28: 3. Rumah dalam kondisi layak/rusak ringan;
B29: 4. Memiliki rumah lebih dari 1;
B30: 5. Pernah memperoleh BSPS dalam kurun waktu 10 tahun;
B31: 6. Penghasilan lebih dari ½ UMP/UMK (BSPS Sejahtera); atau Penghasilan lebih dari UMP/UMK (BSPS);
B32: 7. Memilih untuk dibantu dengan sumber anggaran lain;
B33: 8. Menghuni kurang dari 3 tahun;
B34: 9. Lainnya (diisi pada kolom keterangan).
O35: Diketahui Oleh
O36: =IF('II-4'!A5="Desa","Kepala Desa","Lurah")
O37: =PROPER(Source!B4)
O44: =Source!B5
O45: =IF(Source!A4="Desa","","NIP. "&Source!B6)
